Workbook

Sheet Ingresos
A1: 💰 CONTROL DE INGRESOS - AÑO COMPLETO
A3: AÑO: | B3: 2026 | D3: 🟨 Físico = efectivo | 🟩 Digital = banco/transferencias
A5: 👩 INGRESOS DE IRENE
A6: Concepto | B6: Tipo | C6: F/D | D6: Ene | E6: Feb | F6: Mar | G6: Abr | H6: May | I6: Jun | J6: Jul | K6: Ago | L6: Sep | M6: Oct | N6: Nov | O6: Dic | P6: TOTAL
A7: Nómina | B7: Fijo | C7: F | D7: 0 | E7: 0 | F7: 0 | G7: 0 | H7: 0 | I7: 0 | J7: 0 | K7: 0 | L7: 0 | M7: 0 | N7: 0 | O7: 0 | P7: =SUM(D7:O7) -> 0
C8: D | D8: 49 | E8: 0 | F8: 0 | G8: 0 | H8: 0 | I8: 0 | J8: 0 | K8: 0 | L8: 0 | M8: 0 | N8: 0 | O8: 0 | P8: =SUM(D8:O8) -> 49
A9: Pagas extra | B9: Fijo | C9: F | D9: 0 | E9: 0 | F9: 0 | G9: 0 | H9: 0 | I9: 0 | J9: 0 | K9: 0 | L9: 0 | M9: 0 | N9: 0 | O9: 0 | P9: =SUM(D9:O9) -> 0
C10: D | D10: 0 | E10: 0 | F10: 0 | G10: 0 | H10: 0 | I10: 0 | J10: 0 | K10: 0 | L10: 0 | M10: 0 | N10: 0 | O10: 0 | P10: =SUM(D10:O10) -> 0
A11: Freelance/Extra | B11: Variable | C11: F | D11: 0 | E11: 0 | F11: 0 | G11: 0 | H11: 0 | I11: 0 | J11: 0 | K11: 0 | L11: 0 | M11: 0 | N11: 0 | O11: 0 | P11: =SUM(D11:O11) -> 0
C12: D | D12: 0 | E12: 0 | F12: 0 | G12: 0 | H12: 0 | I12: 0 | J12: 0 | K12: 0 | L12: 0 | M12: 0 | N12: 0 | O12: 0 | P12: =SUM(D12:O12) -> 0
A13: Becas/Ayudas | B13: Variable | C13: F | D13: 0 | E13: 0 | F13: 0 | G13: 0 | H13: 0 | I13: 0 | J13: 0 | K13: 0 | L13: 0 | M13: 0 | N13: 0 | O13: 0 | P13: =SUM(D13:O13) -> 0
C14: D | D14: 0 | E14: 0 | F14: 0 | G14: 0 | H14: 0 | I14: 0 | J14: 0 | K14: 0 | L14: 0 | M14: 0 | N14: 0 | O14: 0 | P14: =SUM(D14:O14) -> 0
A15: Otros ingresos | B15: Variable | C15: F | D15: 0 | E15: 0 | F15: 0 | G15: 0 | H15: 0 | I15: 0 | J15: 0 | K15: 0 | L15: 0 | M15: 0 | N15: 0 | O15: 0 | P15: =SUM(D15:O15) -> 0
C16: D | D16: 0 | E16: 0 | F16: 0 | G16: 0 | H16: 0 | I16: 0 | J16: 0 | K16: 0 | L16: 0 | M16: 0 | N16: 0 | O16: 0 | P16: =SUM(D16:O16) -> 0
A17: TOTAL FÍSICO IRENE | D17: =D7+D9+D11+D13+D15 -> 0 | E17: =E7+E9+E11+E13+E15 -> 0 | F17: =F7+F9+F11+F13+F15 -> 0 | G17: =G7+G9+G11+G13+G15 -> 0 | H17: =H7+H9+H11+H13+H15 -> 0 | I17: =I7+I9+I11+I13+I15 -> 0 | J17: =J7+J9+J11+J13+J15 -> 0 | K17: =K7+K9+K11+K13+K15 -> 0 | ... P17: =P7+P9+P11+P13+P15 -> 0
A18: TOTAL DIGITAL IRENE | D18: =D8+D10+D12+D14+D16 -> 49 | E18: =E8+E10+E12+E14+E16 -> 0 | F18: =F8+F10+F12+F14+F16 -> 0 | G18: =G8+G10+G12+G14+G16 -> 0 | H18: =H8+H10+H12+H14+H16 -> 0 | I18: =I8+I10+I12+I14+I16 -> 0 | J18: =J8+J10+J12+J14+J16 -> 0 | K18: =K8+K10+K12+K14+K16 -> 0 | ... P18: =P8+P10+P12+P14+P16 -> 49
A19: TOTAL IRENE | D19: =D17+D18 -> 49 | E19: =E17+E18 -> 0 | F19: =F17+F18 -> 0 | G19: =G17+G18 -> 0 | H19: =H17+H18 -> 0 | I19: =I17+I18 -> 0 | J19: =J17+J18 -> 0 | K19: =K17+K18 -> 0 | ... P19: =P17+P18 -> 49
A21: 👨 INGRESOS DE VICENTE
A22: Concepto | B22: Tipo | C22: F/D | D22: Ene | E22: Feb | F22: Mar | G22: Abr | H22: May | I22: Jun | J22: Jul | K22: Ago | L22: Sep | M22: Oct | N22: Nov | O22: Dic | P22: TOTAL
A23: Nómina | B23: Fijo | C23: F | D23: 0 | E23: 0 | F23: 0 | G23: 0 | H23: 0 | I23: 0 | J23: 0 | K23: 0 | L23: 0 | M23: 0 | N23: 0 | O23: 0 | P23: =SUM(D23:O23) -> 0
C24: D | D24: =881.44 -> 881.44 | E24: 881.44 | F24: =881.44+3500+300 -> 4681.44 | G24: =881.44+3500+300 -> 4681.44 | H24: =881.44+3500+300 -> 4681.44 | I24: =881.44+3500+300 -> 4681.44 | J24: 3500 | K24: 3500 | L24: 3500 | M24: 3500 | N24: 3500 | O24: 3500 | P24: =SUM(D24:O24) -> 41488.64
A25: Pagas extra | B25: Fijo | C25: F | D25: 0 | E25: 0 | F25: 0 | G25: 0 | H25: 0 | I25: 0 | J25: 0 | K25: 0 | L25: 0 | M25: 0 | N25: 0 | O25: 0 | P25: =SUM(D25:O25) -> 0
C26: D | D26: 0 | E26: 0 | F26: 0 | G26: 0 | H26: 0 | I26: 0 | J26: 0 | K26: 0 | L26: 0 | M26: 0 | N26: 0 | O26: 0 | P26: =SUM(D26:O26) -> 0
A27: Freelance/Extra | B27: Variable | C27: F | D27: 0 | E27: 0 | F27: 0 | G27: 0 | H27: 0 | I27: 0 | J27: 0 | K27: 0 | L27: 0 | M27: 0 | N27: 0 | O27: 0 | P27: =SUM(D27:O27) -> 0
C28: D | D28: 0 | E28: 0 | F28: 0 | G28: 0 | H28: 0 | I28: 0 | J28: 0 | K28: 0 | L28: 0 | M28: 0 | N28: 0 | O28: 0 | P28: =SUM(D28:O28) -> 0
A29: Becas/Ayudas | B29: Variable | C29: F | D29: 0 | E29: 0 | F29: 0 | G29: 0 | H29: 0 | I29: 0 | J29: 0 | K29: 0 | L29: 0 | M29: 0 | N29: 0 | O29: 0 | P29: =SUM(D29:O29) -> 0
C30: D | D30: 0 | E30: 0 | F30: 0 | G30: 0 | H30: 0 | I30: 0 | J30: 0 | K30: 0 | L30: 0 | M30: 0 | N30: 0 | O30: 0 | P30: =SUM(D30:O30) -> 0
A31: Otros ingresos | B31: Variable | C31: F | D31: 0 | E31: 0 | F31: 0 | G31: 0 | H31: 0 | I31: 0 | J31: 0 | K31: 0 | L31: 0 | M31: 0 | N31: 0 | O31: 0 | P31: =SUM(D31:O31) -> 0
C32: D | D32: 0 | E32: 0 | F32: 0 | G32: 0 | H32: 0 | I32: 0 | J32: 0 | K32: 0 | L32: 0 | M32: 0 | N32: 0 | O32: 0 | P32: =SUM(D32:O32) -> 0
A33: TOTAL FÍSICO VICENTE | D33: =D23+D25+D27+D29+D31 -> 0 | E33: =E23+E25+E27+E29+E31 -> 0 | F33: =F23+F25+F27+F29+F31 -> 0 | G33: =G23+G25+G27+G29+G31 -> 0 | H33: =H23+H25+H27+H29+H31 -> 0 | I33: =I23+I25+I27+I29+I31 -> 0 | J33: =J23+J25+J27+J29+J31 -> 0 | K33: =K23+K25+K27+K29+K31 -> 0 | ... P33: =P23+P25+P27+P29+P31 -> 0
A34: TOTAL DIGITAL VICENTE | D34: =D24+D26+D28+D30+D32 -> 881.44 | E34: =E24+E26+E28+E30+E32 -> 881.44 | F34: =F24+F26+F28+F30+F32 -> 4681.44 | G34: =G24+G26+G28+G30+G32 -> 4681.44 | H34: =H24+H26+H28+H30+H32 -> 4681.44 | I34: =I24+I26+I28+I30+I32 -> 4681.44 | J34: =J24+J26+J28+J30+J32 -> 3500 | K34: =K24+K26+K28+K30+K32 -> 3500 | ... P34: =P24+P26+P28+P30+P32 -> 41488.64
A35: TOTAL VICENTE | D35: =D33+D34 -> 881.44 | E35: =E33+E34 -> 881.44 | F35: =F33+F34 -> 4681.44 | G35: =G33+G34 -> 4681.44 | H35: =H33+H34 -> 4681.44 | I35: =I33+I34 -> 4681.44 | J35: =J33+J34 -> 3500 | K35: =K33+K34 -> 3500 | ... P35: =P33+P34 -> 41488.64

Sheet Gastos
A1: 💸 CONTROL DE GASTOS - AÑO COMPLETO
A3: AÑO: | B3: =Ingresos!B3 -> 2026
A5: 👩 GASTOS DE IRENE (comunes + personales)
A6: Concepto | B6: Tipo | C6: F/D | D6: Ene | E6: Feb | F6: Mar | G6: Abr | H6: May | I6: Jun | J6: Jul | K6: Ago | L6: Sep | M6: Oct | N6: Nov | O6: Dic | P6: TOTAL
A7: Alquiler (su parte) | B7: Fijo | C7: F | D7: 0 | E7: 0 | F7: 0 | G7: 0 | H7: 0 | I7: 0 | J7: 0 | K7: 0 | L7: 0 | M7: 0 | N7: 0 | O7: 0 | P7: =SUM(D7:O7) -> 0
C8: D | D8: 0 | E8: 250 | F8: 250 | G8: 250 | H8: 250 | I8: 188 | J8: 0 | K8: 0 | L8: 0 | M8: 0 | N8: 0 | O8: 0 | P8: =SUM(D8:O8) -> 1188
A9: Suministros | B9: Variable | C9: F | D9: 0 | E9: 0 | F9: 0 | G9: 0 | H9: 0 | I9: 0 | J9: 0 | K9: 0 | L9: 0 | M9: 0 | N9: 0 | O9: 0 | P9: =SUM(D9:O9) -> 0
C10: D | D10: 0 | E10: 0 | F10: 0 | G10: 0 | H10: 0 | I10: 0 | J10: 0 | K10: 0 | L10: 0 | M10: 0 | N10: 0 | O10: 0 | P10: =SUM(D10:O10) -> 0
A11: Internet+Móvil | B11: Fijo | C11: F | D11: 0 | E11: 0 | F11: 0 | G11: 0 | H11: 0 | I11: 0 | J11: 0 | K11: 0 | L11: 0 | M11: 0 | N11: 0 | O11: 0 | P11: =SUM(D11:O11) -> 0
C12: D | D12: 0 | E12: 0 | F12: 0 | G12: 0 | H12: 0 | I12: 0 | J12: 0 | K12: 0 | L12: 0 | M12: 0 | N12: 0 | O12: 0 | P12: =SUM(D12:O12) -> 0
A13: Supermercado | B13: Variable | C13: F | D13: 0 | E13: 0 | F13: 0 | G13: 0 | H13: 0 | I13: 0 | J13: 0 | K13: 0 | L13: 0 | M13: 0 | N13: 0 | O13: 0 | P13: =SUM(D13:O13) -> 0
C14: D | D14: 0 | E14: 0 | F14: 0 | G14: 0 | H14: 0 | I14: 0 | J14: 0 | K14: 0 | L14: 0 | M14: 0 | N14: 0 | O14: 0 | P14: =SUM(D14:O14) -> 0
A15: Transporte | B15: Variable | C15: F | D15: 0 | E15: 0 | F15: 0 | G15: 0 | H15: 0 | I15: 0 | J15: 0 | K15: 0 | L15: 0 | M15: 0 | N15: 0 | O15: 0 | P15: =SUM(D15:O15) -> 0
C16: D | D16: 0 | E16: 0 | F16: 0 | G16: 0 | H16: 0 | I16: 0 | J16: 0 | K16: 0 | L16: 0 | M16: 0 | N16: 0 | O16: 0 | P16: =SUM(D16:O16) -> 0
A17: Ocio/Restaurantes | B17: Variable | C17: F | D17: 0 | E17: 0 | F17: 0 | G17: 0 | H17: 0 | I17: 0 | J17: 0 | K17: 0 | L17: 0 | M17: 0 | N17: 0 | O17: 0 | P17: =SUM(D17:O17) -> 0
C18: D | D18: 0 | E18: 0 | F18: 0 | G18: 0 | H18: 0 | I18: 0 | J18: 0 | K18: 0 | L18: 0 | M18: 0 | N18: 0 | O18: 0 | P18: =SUM(D18:O18) -> 0
A19: Ropa/Calzado | B19: Variable | C19: F | D19: 0 | E19: 0 | F19: 0 | G19: 0 | H19: 0 | I19: 0 | J19: 0 | K19: 0 | L19: 0 | M19: 0 | N19: 0 | O19: 0 | P19: =SUM(D19:O19) -> 0
C20: D | D20: 0 | E20: 0 | F20: 0 | G20: 0 | H20: 0 | I20: 0 | J20: 0 | K20: 0 | L20: 0 | M20: 0 | N20: 0 | O20: 0 | P20: =SUM(D20:O20) -> 0
A21: Salud | B21: Variable | C21: F | D21: 0 | E21: 0 | F21: 0 | G21: 0 | H21: 0 | I21: 0 | J21: 0 | K21: 0 | L21: 0 | M21: 0 | N21: 0 | O21: 0 | P21: =SUM(D21:O21) -> 0
C22: D | D22: 0 | E22: 0 | F22: 0 | G22: 0 | H22: 0 | I22: 0 | J22: 0 | K22: 0 | L22: 0 | M22: 0 | N22: 0 | O22: 0 | P22: =SUM(D22:O22) -> 0
A23: Suscripciones | B23: Fijo | C23: F | D23: 0 | E23: 0 | F23: 0 | G23: 0 | H23: 0 | I23: 0 | J23: 0 | K23: 0 | L23: 0 | M23: 0 | N23: 0 | O23: 0 | P23: =SUM(D23:O23) -> 0
C24: D | D24: 0 | E24: 0 | F24: 0 | G24: 0 | H24: 0 | I24: 0 | J24: 0 | K24: 0 | L24: 0 | M24: 0 | N24: 0 | O24: 0 | P24: =SUM(D24:O24) -> 0
A25: Otros gastos | B25: Variable | C25: F | D25: 0 | E25: 0 | F25: 0 | G25: 0 | H25: 0 | I25: 0 | J25: 0 | K25: 0 | L25: 0 | M25: 0 | N25: 0 | O25: 0 | P25: =SUM(D25:O25) -> 0
C26: D | D26: 0 | E26: 0 | F26: 0 | G26: 0 | H26: 0 | I26: 0 | J26: 0 | K26: 0 | L26: 0 | M26: 0 | N26: 0 | O26: 0 | P26: =SUM(D26:O26) -> 0
A27: TOTAL FÍSICO IRENE | D27: =D7+D9+D11+D13+D15+D17+D19+D21+D23+D25 -> 0 | E27: =E7+E9+E11+E13+E15+E17+E19+E21+E23+E25 -> 0 | F27: =F7+F9+F11+F13+F15+F17+F19+F21+F23+F25 -> 0 | G27: =G7+G9+G11+G13+G15+G17+G19+G21+G23+G25 -> 0 | H27: =H7+H9+H11+H13+H15+H17+H19+H21+H23+H25 -> 0 | I27: =I7+I9+I11+I13+I15+I17+I19+I21+I23+I25 -> 0 | J27: =J7+J9+J11+J13+J15+J17+J19+J21+J23+J25 -> 0 | K27: =K7+K9+K11+K13+K15+K17+K19+K21+K23+K25 -> 0 | ... P27: =P7+P9+P11+P13+P15+P17+P19+P21+P23+P25 -> 0
A28: TOTAL DIGITAL IRENE | D28: =D8+D10+D12+D14+D16+D18+D20+D22+D24+D26 -> 0 | E28: =E8+E10+E12+E14+E16+E18+E20+E22+E24+E26 -> 250 | F28: =F8+F10+F12+F14+F16+F18+F20+F22+F24+F26 -> 250 | G28: =G8+G10+G12+G14+G16+G18+G20+G22+G24+G26 -> 250 | H28: =H8+H10+H12+H14+H16+H18+H20+H22+H24+H26 -> 250 | I28: =I8+I10+I12+I14+I16+I18+I20+I22+I24+I26 -> 188 | J28: =J8+J10+J12+J14+J16+J18+J20+J22+J24+J26 -> 0 | K28: =K8+K10+K12+K14+K16+K18+K20+K22+K24+K26 -> 0 | ... P28: =P8+P10+P12+P14+P16+P18+P20+P22+P24+P26 -> 1188
A29: TOTAL GASTOS IRENE | D29: =D27+D28 -> 0 | E29: =E27+E28 -> 250 | F29: =F27+F28 -> 250 | G29: =G27+G28 -> 250 | H29: =H27+H28 -> 250 | I29: =I27+I28 -> 188 | J29: =J27+J28 -> 0 | K29: =K27+K28 -> 0 | ... P29: =P27+P28 -> 1188
A31: 👨 GASTOS DE VICENTE (comunes + personales)
A32: Concepto | B32: Tipo | C32: F/D | D32: Ene | E32: Feb | F32: Mar | G32: Abr | H32: May | I32: Jun | J32: Jul | K32: Ago | L32: Sep | M32: Oct | N32: Nov | O32: Dic | P32: TOTAL
A33: Alquiler (su parte) | B33: Fijo | C33: F | D33: 0 | E33: 0 | F33: 0 | G33: 0 | H33: 0 | I33: 0 | J33: 0 | K33: 0 | L33: 0 | M33: 0 | N33: 0 | O33: 0 | P33: =SUM(D33:O33) -> 0
C34: D | D34: 0 | E34: 250 | F34: 250 | G34: 250 | H34: 250 | I34: 187 | J34: 0 | K34: 0 | L34: 0 | M34: 0 | N34: 0 | O34: 0 | P34: =SUM(D34:O34) -> 1187
A35: Suministros | B35: Variable | C35: F | D35: 0 | E35: 0 | F35: 0 | G35: 0 | H35: 0 | I35: 0 | J35: 0 | K35: 0 | L35: 0 | M35: 0 | N35: 0 | O35: 0 | P35: =SUM(D35:O35) -> 0
C36: D | D36: 0 | E36: 0 | F36: 0 | G36: 0 | H36: 0 | I36: 0 | J36: 0 | K36: 0 | L36: 0 | M36: 0 | N36: 0 | O36: 0 | P36: =SUM(D36:O36) -> 0
A37: Internet+Móvil | B37: Fijo | C37: F | D37: 0 | E37: 0 | F37: 0 | G37: 0 | H37: 0 | I37: 0 | J37: 0 | K37: 0 | L37: 0 | M37: 0 | N37: 0 | O37: 0 | P37: =SUM(D37:O37) -> 0
C38: D | D38: 0 | E38: 0 | F38: 0 | G38: 0 | H38: 0 | I38: 0 | J38: 0 | K38: 0 | L38: 0 | M38: 0 | N38: 0 | O38: 0 | P38: =SUM(D38:O38) -> 0
A39: Supermercado | B39: Variable | C39: F | D39: 0 | E39: 0 | F39: 0 | G39: 0 | H39: 0 | I39: 0 | J39: 0 | K39: 0 | L39: 0 | M39: 0 | N39: 0 | O39: 0 | P39: =SUM(D39:O39) -> 0
C40: D | D40: 0 | E40: 0 | F40: 0 | G40: 0 | H40: 0 | I40: 0 | J40: 0 | K40: 0 | L40: 0 | M40: 0 | N40: 0 | O40: 0 | P40: =SUM(D40:O40) -> 0
A41: Transporte | B41: Variable | C41: F | D41: 0 | E41: 0 | F41: 0 | G41: 0 | H41: 0 | I41: 0 | J41: 0 | K41: 0 | L41: 0 | M41: 0 | N41: 0 | O41: 0 | P41: =SUM(D41:O41) -> 0
C42: D | D42: 0 | E42: 0 | F42: 0 | G42: 0 | H42: 0 | I42: 0 | J42: 0 | K42: 0 | L42: 0 | M42: 0 | N42: 0 | O42: 0 | P42: =SUM(D42:O42) -> 0
A43: Ocio/Restaurantes | B43: Variable | C43: F | D43: 0 | E43: 0 | F43: 0 | G43: 0 | H43: 0 | I43: 0 | J43: 0 | K43: 0 | L43: 0 | M43: 0 | N43: 0 | O43: 0 | P43: =SUM(D43:O43) -> 0
...

Sheet Balance y Saldos
A1: 💰 BALANCE MENSUAL Y EVOLUCIÓN DE SALDOS
A3: AÑO: | B3: =Ingresos!B3 -> 2026
A5: 💵 SALDOS INICIALES (a 11 de enero 2026)
A6: Cuenta | B6: Físico (€) | C6: Digital (€) | D6: Total (€)
A7: Irene | B7: 3000 | C7: 10898.1 | D7: =B7+C7 -> 13898.1
A8: Vicente | B8: 15 | C8: 28.82 | D8: =B8+C8 -> 43.82
A9: Cuenta Conjunta | B9: 0 | C9: 2000 | D9: =B9+C9 -> 2000
A11: 👩 BALANCE MENSUAL IRENE
A12: Concepto | C12: Ene | D12: Feb | E12: Mar | F12: Abr | G12: May | H12: Jun | I12: Jul | J12: Ago | K12: Sep | L12: Oct | M12: Nov | N12: Dic | O12: TOTAL
A13: Ingresos (F+D) | C13: =Ingresos!D19 -> 49 | D13: =Ingresos!E19 -> 0 | E13: =Ingresos!F19 -> 0 | F13: =Ingresos!G19 -> 0 | G13: =Ingresos!H19 -> 0 | H13: =Ingresos!I19 -> 0 | I13: =Ingresos!J19 -> 0 | J13: =Ingresos!K19 -> 0 | ... O13: =Ingresos!P19 -> 49
A14: Gastos (F+D) | C14: =Gastos!D29 -> 0 | D14: =Gastos!E29 -> 250 | E14: =Gastos!F29 -> 250 | F14: =Gastos!G29 -> 250 | G14: =Gastos!H29 -> 250 | H14: =Gastos!I29 -> 188 | I14: =Gastos!J29 -> 0 | J14: =Gastos!K29 -> 0 | ... O14: =Gastos!P29 -> 1188
A15: Ahorro del mes | C15: =C13-C14 -> 49 | D15: =D13-D14 -> -250 | E15: =E13-E14 -> -250 | F15: =F13-F14 -> -250 | G15: =G13-G14 -> -250 | H15: =H13-H14 -> -188 | I15: =I13-I14 -> 0 | J15: =J13-J14 -> 0 | ... O15: =O13-O14 -> -1139
A16: Transferencia → Conjunta | C16: 0 | D16: 0 | E16: 0 | F16: 0 | G16: 0 | H16: 0 | I16: 0 | J16: 0 | K16: 0 | L16: 0 | M16: 0 | N16: 0 | O16: =SUM(C16:N16) -> 0
A17: SALDO IRENE | C17: =$D$7+C15-C16 -> 13947.1 | D17: =C17+D15-D16 -> 13697.1 | E17: =D17+E15-E16 -> 13447.1 | F17: =E17+F15-F16 -> 13197.1 | G17: =F17+G15-G16 -> 12947.1 | H17: =G17+H15-H16 -> 12759.1 | I17: =H17+I15-I16 -> 12759.1 | J17: =I17+J15-J16 -> 12759.1 | K17: =J17+K15-K16 -> 12759.1 | ... N17: =M17+N15-N16 -> 12759.1 | O17: =N17 -> 12759.1
A19: 👨 BALANCE MENSUAL VICENTE
A20: Concepto | C20: Ene | D20: Feb | E20: Mar | F20: Abr | G20: May | H20: Jun | I20: Jul | J20: Ago | K20: Sep | L20: Oct | M20: Nov | N20: Dic | O20: TOTAL
A21: Ingresos (F+D) | C21: =Ingresos!D35 -> 881.44 | D21: =Ingresos!E35 -> 881.44 | E21: =Ingresos!F35 -> 4681.44 | F21: =Ingresos!G35 -> 4681.44 | G21: =Ingresos!H35 -> 4681.44 | H21: =Ingresos!I35 -> 4681.44 | I21: =Ingresos!J35 -> 3500 | J21: =Ingresos!K35 -> 3500 | ... O21: =Ingresos!P35 -> 41488.64
A22: Gastos (F+D) | C22: =Gastos!D55 -> 0 | D22: =Gastos!E55 -> 250 | E22: =Gastos!F55 -> 250 | F22: =Gastos!G55 -> 250 | G22: =Gastos!H55 -> 250 | H22: =Gastos!I55 -> 187 | I22: =Gastos!J55 -> 0 | J22: =Gastos!K55 -> 0 | ... O22: =Gastos!P55 -> 1187
A23: Ahorro del mes | C23: =C21-C22 -> 881.44 | D23: =D21-D22 -> 631.44 | E23: =E21-E22 -> 4431.44 | F23: =F21-F22 -> 4431.44 | G23: =G21-G22 -> 4431.44 | H23: =H21-H22 -> 4494.44 | I23: =I21-I22 -> 3500 | J23: =J21-J22 -> 3500 | ... O23: =O21-O22 -> 40301.64
A24: Transferencia → Conjunta | C24: 0 | D24: 0 | E24: 0 | F24: 0 | G24: 0 | H24: 0 | I24: 0 | J24: 0 | K24: 0 | L24: 0 | M24: 0 | N24: 0 | O24: =SUM(C24:N24) -> 0
A25: SALDO VICENTE | C25: =$D$8+C23-C24 -> 925.26 | D25: =C25+D23-D24 -> 1556.7 | E25: =D25+E23-E24 -> 5988.14 | F25: =E25+F23-F24 -> 10419.58 | G25: =F25+G23-G24 -> 14851.02 | H25: =G25+H23-H24 -> 19345.46 | I25: =H25+I23-I24 -> 22845.46 | J25: =I25+J23-J24 -> 26345.46 | K25: =J25+K23-K24 -> 29845.46 | ... N25: =M25+N23-N24 -> 40345.46 | O25: =N25 -> 40345.46
A27: 🏦 CUENTA CONJUNTA (Hucha para el piso)
A28: Concepto | C28: Ene | D28: Feb | E28: Mar | F28: Abr | G28: May | H28: Jun | I28: Jul | J28: Ago | K28: Sep | L28: Oct | M28: Nov | N28: Dic | O28: TOTAL
A29: Aportación Irene | C29: =C16 -> 0 | D29: =D16 -> 0 | E29: =E16 -> 0 | F29: =F16 -> 0 | G29: =G16 -> 0 | H29: =H16 -> 0 | I29: =I16 -> 0 | J29: =J16 -> 0 | ... O29: =O16 -> 0
A30: Aportación Vicente | C30: =C24 -> 0 | D30: =D24 -> 0 | E30: =E24 -> 0 | F30: =F24 -> 0 | G30: =G24 -> 0 | H30: =H24 -> 0 | I30: =I24 -> 0 | J30: =J24 -> 0 | ... O30: =O24 -> 0
A31: Otros (intereses, etc) | C31: 0 | D31: 0 | E31: 0 | F31: 0 | G31: 0 | H31: 0 | I31: 0 | J31: 0 | K31: 0 | L31: 0 | M31: 0 | N31: 0 | O31: =SUM(C31:N31) -> 0
A32: SALDO CONJUNTA | C32: =$D$9+C29+C30+C31 -> 2000 | D32: =C32+D29+D30+D31 -> 2000 | E32: =D32+E29+E30+E31 -> 2000 | F32: =E32+F29+F30+F31 -> 2000 | G32: =F32+G29+G30+G31 -> 2000 | H32: =G32+H29+H30+H31 -> 2000 | I32: =H32+I29+I30+I31 -> 2000 | J32: =I32+J29+J30+J31 -> 2000 | K32: =J32+K29+K30+K31 -> 2000 | ... N32: =M32+N29+N30+N31 -> 2000 | O32: =N32 -> 2000
A34: 📊 RESUMEN: PATRIMONIO TOTAL
C35: Ene | D35: Feb | E35: Mar | F35: Abr | G35: May | H35: Jun | I35: Jul | J35: Ago | K35: Sep | L35: Oct | M35: Nov | N35: Dic | O35: FINAL
A36: Saldo Irene | C36: =C17 -> 13947.1 | D36: =D17 -> 13697.1 | E36: =E17 -> 13447.1 | F36: =F17 -> 13197.1 | G36: =G17 -> 12947.1 | H36: =H17 -> 12759.1 | I36: =I17 -> 12759.1 | J36: =J17 -> 12759.1 | ... O36: =O17 -> 12759.1
A37: Saldo Vicente | C37: =C25 -> 925.26 | D37: =D25 -> 1556.7 | E37: =E25 -> 5988.14 | F37: =F25 -> 10419.58 | G37: =G25 -> 14851.02 | H37: =H25 -> 19345.46 | I37: =I25 -> 22845.46 | J37: =J25 -> 26345.46 | ... O37: =O25 -> 40345.46
A38: Saldo Conjunta | C38: =C32 -> 2000 | D38: =D32 -> 2000 | E38: =E32 -> 2000 | F38: =F32 -> 2000 | G38: =G32 -> 2000 | H38: =H32 -> 2000 | I38: =I32 -> 2000 | J38: =J32 -> 2000 | ... O38: =O32 -> 2000
A39: TOTAL PATRIMONIO | C39: =C36+C37+C38 -> 16872.36 | D39: =D36+D37+D38 -> 17253.8 | E39: =E36+E37+E38 -> 21435.24 | F39: =F36+F37+F38 -> 25616.68 | G39: =G36+G37+G38 -> 29798.12 | H39: =H36+H37+H38 -> 34104.56 | I39: =I36+I37+I38 -> 37604.56 | J39: =J36+J37+J38 -> 41104.56 | ... O39: =O36+O37+O38 -> 55104.56

Sheet Compra Piso
A1: 🏠 PLANIFICACIÓN COMPRA VIVIENDA - VALENCIA
A3: 💵 DINERO DISPONIBLE (a fin de año)
A4: Saldo Irene (dic) | B4: ='Balance y Saldos'!O17 -> 12759.1
A5: Saldo Vicente (dic) | B5: ='Balance y Saldos'!O25 -> 40345.46
A6: Saldo Conjunta (dic) | B6: ='Balance y Saldos'!O32 -> 2000
A7: TOTAL DISPONIBLE | B7: ='Balance y Saldos'!O39 -> 55104.56
A9: 🏡 DATOS DE LA VIVIENDA
A10: Precio vivienda | B10: 299000
A11: Tipo | B11: Nueva | C11: Nueva / Segunda mano
A12: ¿Menor 35 años? | B12: Sí | C12: Sí=6% / No=10%
A14: 📋 GASTOS DE COMPRA
A15: ITP (2ª mano) | B15: =IF(B12="Sí",B10*0.06,B10*0.1) -> 17940
A16: IVA (nueva) | B16: =IF(B11="Nueva",B10*0.1,0) -> 29900
A17: AJD (nueva) | B17: =IF(B11="Nueva",B10*0.015,0) -> 4485
A18: Notaría+Registro+Gestoría | B18: 1800
A19: Tasación | B19: 400
A20: TOTAL GASTOS | B20: =B15+B16+B17+B18+B19 -> 54525
A22: 🏦 HIPOTECA
A23: % Financiación | B23: 0.8
A24: Importe hipoteca | B24: =B10*B23 -> 239200
A25: ENTRADA | B25: =B10-B24 -> 59800
A27: TIN Anual | B27: 0.03
A28: Plazo (años) | B28: 30
A29: CUOTA MENSUAL | B29: =PMT(B27/12,B28*12,-B24) -> 1008.4768
A31: Ingresos netos/mes | B31: 3000
A32: RATIO ENDEUDAMIENTO | B32: =B29/B31 -> 0.33615895
A33: Estado | B33: =IF(B32<0.3,"✅ ÓPTIMO",IF(B32<0.35,"⚠️ OK","❌ ALTO")) -> ⚠️ OK
A35: 💰 ¿CUÁNTO NECESITAMOS?
A36: Entrada | B36: =B25 -> 59800
A37: Gastos compra | B37: =B20 -> 54525
A38: Muebles/Reformas | B38: 0
A39: Colchón emergencia | B39: 3000
A40: TOTAL NECESARIO | B40: =B36+B37+B38+B39 -> 117325
A42: Disponible | B42: =B7 -> 55104.56
A43: FALTA | B43: =MAX(0,B40-B42) -> 62220.44
A45: Ahorro mensual est. | B45: 800
A46: Meses necesarios | B46: =IF(B43=0,0,CEILING(B43/B45,1)) -> 78
A47: Fecha estimada | B47: =IF(B43=0,"¡Ya!",EDATE(TODAY(),B46)) -> 48429

Sheet Gráficos
A1: 📊 DASHBOARD DE GRÁFICOS
A3: DATOS PARA GRÁFICOS (no modificar)
A4: Concepto | B4: Ene | C4: Feb | D4: Mar | E4: Abr | F4: May | G4: Jun | H4: Jul | I4: Ago | J4: Sep | K4: Oct | L4: Nov | M4: Dic
A5: Ing. Irene | B5: =Ingresos!D19 -> 49 | C5: =Ingresos!E19 -> 0 | D5: =Ingresos!F19 -> 0 | E5: =Ingresos!G19 -> 0 | F5: =Ingresos!H19 -> 0 | G5: =Ingresos!I19 -> 0 | H5: =Ingresos!J19 -> 0 | I5: =Ingresos!K19 -> 0 | ... M5: =Ingresos!O19 -> 0
A6: Ing. Vicente | B6: =Ingresos!D35 -> 881.44 | C6: =Ingresos!E35 -> 881.44 | D6: =Ingresos!F35 -> 4681.44 | E6: =Ingresos!G35 -> 4681.44 | F6: =Ingresos!H35 -> 4681.44 | G6: =Ingresos!I35 -> 4681.44 | H6: =Ingresos!J35 -> 3500 | I6: =Ingresos!K35 -> 3500 | ... M6: =Ingresos!O35 -> 3500
A7: Gast. Irene | B7: =Gastos!D29 -> 0 | C7: =Gastos!E29 -> 250 | D7: =Gastos!F29 -> 250 | E7: =Gastos!G29 -> 250 | F7: =Gastos!H29 -> 250 | G7: =Gastos!I29 -> 188 | H7: =Gastos!J29 -> 0 | I7: =Gastos!K29 -> 0 | ... M7: =Gastos!O29 -> 0
A8: Gast. Vicente | B8: =Gastos!D55 -> 0 | C8: =Gastos!E55 -> 250 | D8: =Gastos!F55 -> 250 | E8: =Gastos!G55 -> 250 | F8: =Gastos!H55 -> 250 | G8: =Gastos!I55 -> 187 | H8: =Gastos!J55 -> 0 | I8: =Gastos!K55 -> 0 | ... M8: =Gastos!O55 -> 0
A9: Aport. Irene | B9: ='Balance y Saldos'!C16 -> 0 | C9: ='Balance y Saldos'!D16 -> 0 | D9: ='Balance y Saldos'!E16 -> 0 | E9: ='Balance y Saldos'!F16 -> 0 | F9: ='Balance y Saldos'!G16 -> 0 | G9: ='Balance y Saldos'!H16 -> 0 | H9: ='Balance y Saldos'!I16 -> 0 | I9: ='Balance y Saldos'!J16 -> 0 | ... M9: ='Balance y Saldos'!N16 -> 0
A10: Aport. Vicente | B10: ='Balance y Saldos'!C24 -> 0 | C10: ='Balance y Saldos'!D24 -> 0 | D10: ='Balance y Saldos'!E24 -> 0 | E10: ='Balance y Saldos'!F24 -> 0 | F10: ='Balance y Saldos'!G24 -> 0 | G10: ='Balance y Saldos'!H24 -> 0 | H10: ='Balance y Saldos'!I24 -> 0 | I10: ='Balance y Saldos'!J24 -> 0 | ... M10: ='Balance y Saldos'!N24 -> 0
A11: Saldo Conjunta | B11: ='Balance y Saldos'!C32 -> 2000 | C11: ='Balance y Saldos'!D32 -> 2000 | D11: ='Balance y Saldos'!E32 -> 2000 | E11: ='Balance y Saldos'!F32 -> 2000 | F11: ='Balance y Saldos'!G32 -> 2000 | G11: ='Balance y Saldos'!H32 -> 2000 | H11: ='Balance y Saldos'!I32 -> 2000 | I11: ='Balance y Saldos'!J32 -> 2000 | ... M11: ='Balance y Saldos'!N32 -> 2000
A12: Total Patrimonio | B12: ='Balance y Saldos'!C39 -> 16872.36 | C12: ='Balance y Saldos'!D39 -> 17253.8 | D12: ='Balance y Saldos'!E39 -> 21435.24 | E12: ='Balance y Saldos'!F39 -> 25616.68 | F12: ='Balance y Saldos'!G39 -> 29798.12 | G12: ='Balance y Saldos'!H39 -> 34104.56 | H12: ='Balance y Saldos'!I39 -> 37604.56 | I12: ='Balance y Saldos'!J39 -> 41104.56 | ... M12: ='Balance y Saldos'!N39 -> 55104.56
A14: TOTALES ANUALES
A15: Total Aport. Irene | B15: ='Balance y Saldos'!O16 -> 0
A16: Total Aport. Vicente | B16: ='Balance y Saldos'!O24 -> 0
A18: FÍSICO VS DIGITAL
A19: Ing. Físico Total | B19: =Ingresos!P17+Ingresos!P33 -> 0
A20: Ing. Digital Total | B20: =Ingresos!P18+Ingresos!P34 -> 41537.64
A22: META AHORRO
A23: Necesario | B23: ='Compra Piso'!B40 -> 117325
A24: Disponible | B24: ='Compra Piso'!B7 -> 55104.56
A25: Falta | B25: ='Compra Piso'!B43 -> 62220.44
